2023-11-10 20:52:08,299 - [ERROR] - Internal Server Error: /admin/news/new/add/ - C:\Users\Acer\PycharmProjects\PythonProjects\test_progect\venv\Lib\site-packages\django\utils\log.py - (<class 'kombu.exceptions.OperationalError'>, OperationalError('Error 10061 connecting to localhost:6379. Подключение не установлено, т.к. конечный компьютер отверг запрос на подключение.'), <traceback object at 0x00000286D0022280>) 
Traceback (most recent call last):
  File "C:\Users\Acer\PycharmProjects\PythonProjects\test_progect\venv\Lib\site-packages\redis\connection.py", line 264, in connect
    sock = self.retry.call_with_retry(
           ^^^^^^^^^^^^^^^^^^^^^^^^^^^
  File "C:\Users\Acer\PycharmProjects\PythonProjects\test_progect\venv\Lib\site-packages\redis\retry.py", line 46, in call_with_retry
    return do()
           ^^^^
  File "C:\Users\Acer\PycharmProjects\PythonProjects\test_progect\venv\Lib\site-packages\redis\connection.py", line 265, in <lambda>
    lambda: self._connect(), lambda error: self.disconnect(error)
            ^^^^^^^^^^^^^^^
  File "C:\Users\Acer\PycharmProjects\PythonProjects\test_progect\venv\Lib\site-packages\redis\connection.py", line 627, in _connect
    raise err
  File "C:\Users\Acer\PycharmProjects\PythonProjects\test_progect\venv\Lib\site-packages\redis\connection.py", line 615, in _connect
    sock.connect(socket_address)
ConnectionRefusedError: [WinError 10061] Подключение не установлено, т.к. конечный компьютер отверг запрос на подключение

During handling of the above exception, another exception occurred:

Traceback (most recent call last):
  File "C:\Users\Acer\PycharmProjects\PythonProjects\test_progect\venv\Lib\site-packages\celery\backends\redis.py", line 127, in reconnect_on_error
    yield
  File "C:\Users\Acer\PycharmProjects\PythonProjects\test_progect\venv\Lib\site-packages\celery\backends\redis.py", line 177, in _consume_from
    self._pubsub.subscribe(key)
  File "C:\Users\Acer\PycharmProjects\PythonProjects\test_progect\venv\Lib\site-packages\redis\client.py", line 916, in subscribe
    ret_val = self.execute_command("SUBSCRIBE", *new_channels.keys())
              ^^^^^^^^^^^^^^^^^^^^^^^^^^^^^^^^^^^^^^^^^^^^^^^^^^^^^^^
  File "C:\Users\Acer\PycharmProjects\PythonProjects\test_progect\venv\Lib\site-packages\redis\client.py", line 749, in execute_command
    self.connection = self.connection_pool.get_connection(
                      ^^^^^^^^^^^^^^^^^^^^^^^^^^^^^^^^^^^^
  File "C:\Users\Acer\PycharmProjects\PythonProjects\test_progect\venv\Lib\site-packages\redis\connection.py", line 1086, in get_connection
    connection.connect()
  File "C:\Users\Acer\PycharmProjects\PythonProjects\test_progect\venv\Lib\site-packages\redis\connection.py", line 270, in connect
    raise ConnectionError(self._error_message(e))
redis.exceptions.ConnectionError: Error 10061 connecting to localhost:6379. Подключение не установлено, т.к. конечный компьютер отверг запрос на подключение.

During handling of the above exception, another exception occurred:

Traceback (most recent call last):
  File "C:\Users\Acer\PycharmProjects\PythonProjects\test_progect\venv\Lib\site-packages\redis\connection.py", line 264, in connect
    sock = self.retry.call_with_retry(
           ^^^^^^^^^^^^^^^^^^^^^^^^^^^
  File "C:\Users\Acer\PycharmProjects\PythonProjects\test_progect\venv\Lib\site-packages\redis\retry.py", line 46, in call_with_retry
    return do()
           ^^^^
  File "C:\Users\Acer\PycharmProjects\PythonProjects\test_progect\venv\Lib\site-packages\redis\connection.py", line 265, in <lambda>
    lambda: self._connect(), lambda error: self.disconnect(error)
            ^^^^^^^^^^^^^^^
  File "C:\Users\Acer\PycharmProjects\PythonProjects\test_progect\venv\Lib\site-packages\redis\connection.py", line 627, in _connect
    raise err
  File "C:\Users\Acer\PycharmProjects\PythonProjects\test_progect\venv\Lib\site-packages\redis\connection.py", line 615, in _connect
    sock.connect(socket_address)
ConnectionRefusedError: [WinError 10061] Подключение не установлено, т.к. конечный компьютер отверг запрос на подключение

During handling of the above exception, another exception occurred:

Traceback (most recent call last):
  File "C:\Users\Acer\PycharmProjects\PythonProjects\test_progect\venv\Lib\site-packages\kombu\connection.py", line 472, in _reraise_as_library_errors
    yield
  File "C:\Users\Acer\PycharmProjects\PythonProjects\test_progect\venv\Lib\site-packages\celery\app\base.py", line 797, in send_task
    self.backend.on_task_call(P, task_id)
  File "C:\Users\Acer\PycharmProjects\PythonProjects\test_progect\venv\Lib\site-packages\celery\backends\redis.py", line 373, in on_task_call
    self.result_consumer.consume_from(task_id)
  File "C:\Users\Acer\PycharmProjects\PythonProjects\test_progect\venv\Lib\site-packages\celery\backends\redis.py", line 169, in consume_from
    return self.start(task_id)
           ^^^^^^^^^^^^^^^^^^^
  File "C:\Users\Acer\PycharmProjects\PythonProjects\test_progect\venv\Lib\site-packages\celery\backends\redis.py", line 147, in start
    self._consume_from(initial_task_id)
  File "C:\Users\Acer\PycharmProjects\PythonProjects\test_progect\venv\Lib\site-packages\celery\backends\redis.py", line 176, in _consume_from
    with self.reconnect_on_error():
  File "C:\Users\Acer\AppData\Local\Programs\Python\Python311\Lib\contextlib.py", line 155, in __exit__
    self.gen.throw(typ, value, traceback)
  File "C:\Users\Acer\PycharmProjects\PythonProjects\test_progect\venv\Lib\site-packages\celery\backends\redis.py", line 130, in reconnect_on_error
    self._ensure(self._reconnect_pubsub, ())
  File "C:\Users\Acer\PycharmProjects\PythonProjects\test_progect\venv\Lib\site-packages\celery\backends\redis.py", line 384, in ensure
    return retry_over_time(
           ^^^^^^^^^^^^^^^^
  File "C:\Users\Acer\PycharmProjects\PythonProjects\test_progect\venv\Lib\site-packages\kombu\utils\functional.py", line 318, in retry_over_time
    return fun(*args, **kwargs)
           ^^^^^^^^^^^^^^^^^^^^
  File "C:\Users\Acer\PycharmProjects\PythonProjects\test_progect\venv\Lib\site-packages\celery\backends\redis.py", line 106, in _reconnect_pubsub
    metas = self.backend.client.mget(self.subscribed_to)
            ^^^^^^^^^^^^^^^^^^^^^^^^^^^^^^^^^^^^^^^^^^^^
  File "C:\Users\Acer\PycharmProjects\PythonProjects\test_progect\venv\Lib\site-packages\redis\commands\core.py", line 2015, in mget
    return self.execute_command("MGET", *args, **options)
           ^^^^^^^^^^^^^^^^^^^^^^^^^^^^^^^^^^^^^^^^^^^^^^
  File "C:\Users\Acer\PycharmProjects\PythonProjects\test_progect\venv\Lib\site-packages\redis\client.py", line 533, in execute_command
    conn = self.connection or pool.get_connection(command_name, **options)
                              ^^^^^^^^^^^^^^^^^^^^^^^^^^^^^^^^^^^^^^^^^^^^
  File "C:\Users\Acer\PycharmProjects\PythonProjects\test_progect\venv\Lib\site-packages\redis\connection.py", line 1086, in get_connection
    connection.connect()
  File "C:\Users\Acer\PycharmProjects\PythonProjects\test_progect\venv\Lib\site-packages\redis\connection.py", line 270, in connect
    raise ConnectionError(self._error_message(e))
redis.exceptions.ConnectionError: Error 10061 connecting to localhost:6379. Подключение не установлено, т.к. конечный компьютер отверг запрос на подключение.

The above exception was the direct cause of the following exception:

Traceback (most recent call last):
  File "C:\Users\Acer\PycharmProjects\PythonProjects\test_progect\venv\Lib\site-packages\django\core\handlers\exception.py", line 55, in inner
    response = get_response(request)
               ^^^^^^^^^^^^^^^^^^^^^
  File "C:\Users\Acer\PycharmProjects\PythonProjects\test_progect\venv\Lib\site-packages\django\core\handlers\base.py", line 197, in _get_response
    response = wrapped_callback(request, *callback_args, **callback_kwargs)
               ^^^^^^^^^^^^^^^^^^^^^^^^^^^^^^^^^^^^^^^^^^^^^^^^^^^^^^^^^^^^
  File "C:\Users\Acer\PycharmProjects\PythonProjects\test_progect\venv\Lib\site-packages\django\contrib\admin\options.py", line 688, in wrapper
    return self.admin_site.admin_view(view)(*args, **kwargs)
           ^^^^^^^^^^^^^^^^^^^^^^^^^^^^^^^^^^^^^^^^^^^^^^^^^
  File "C:\Users\Acer\PycharmProjects\PythonProjects\test_progect\venv\Lib\site-packages\django\utils\decorators.py", line 134, in _wrapper_view
    response = view_func(request, *args, **kwargs)
               ^^^^^^^^^^^^^^^^^^^^^^^^^^^^^^^^^^^
  File "C:\Users\Acer\PycharmProjects\PythonProjects\test_progect\venv\Lib\site-packages\django\views\decorators\cache.py", line 62, in _wrapper_view_func
    response = view_func(request, *args, **kwargs)
               ^^^^^^^^^^^^^^^^^^^^^^^^^^^^^^^^^^^
  File "C:\Users\Acer\PycharmProjects\PythonProjects\test_progect\venv\Lib\site-packages\django\contrib\admin\sites.py", line 242, in inner
    return view(request, *args, **kwargs)
           ^^^^^^^^^^^^^^^^^^^^^^^^^^^^^^
  File "C:\Users\Acer\PycharmProjects\PythonProjects\test_progect\venv\Lib\site-packages\django\contrib\admin\options.py", line 1886, in add_view
    return self.changeform_view(request, None, form_url, extra_context)
           ^^^^^^^^^^^^^^^^^^^^^^^^^^^^^^^^^^^^^^^^^^^^^^^^^^^^^^^^^^^^
  File "C:\Users\Acer\PycharmProjects\PythonProjects\test_progect\venv\Lib\site-packages\django\utils\decorators.py", line 46, in _wrapper
    return bound_method(*args, **kwargs)
           ^^^^^^^^^^^^^^^^^^^^^^^^^^^^^
  File "C:\Users\Acer\PycharmProjects\PythonProjects\test_progect\venv\Lib\site-packages\django\utils\decorators.py", line 134, in _wrapper_view
    response = view_func(request, *args, **kwargs)
               ^^^^^^^^^^^^^^^^^^^^^^^^^^^^^^^^^^^
  File "C:\Users\Acer\PycharmProjects\PythonProjects\test_progect\venv\Lib\site-packages\django\contrib\admin\options.py", line 1747, in changeform_view
    return self._changeform_view(request, object_id, form_url, extra_context)
           ^^^^^^^^^^^^^^^^^^^^^^^^^^^^^^^^^^^^^^^^^^^^^^^^^^^^^^^^^^^^^^^^^^
  File "C:\Users\Acer\PycharmProjects\PythonProjects\test_progect\venv\Lib\site-packages\django\contrib\admin\options.py", line 1798, in _changeform_view
    self.save_model(request, new_object, form, not add)
  File "C:\Users\Acer\PycharmProjects\PythonProjects\test_progect\venv\Lib\site-packages\django\contrib\admin\options.py", line 1227, in save_model
    obj.save()
  File "C:\Users\Acer\PycharmProjects\PythonProjects\test_progect\venv\Lib\site-packages\django\db\models\base.py", line 814, in save
    self.save_base(
  File "C:\Users\Acer\PycharmProjects\PythonProjects\test_progect\venv\Lib\site-packages\django\db\models\base.py", line 892, in save_base
    post_save.send(
  File "C:\Users\Acer\PycharmProjects\PythonProjects\test_progect\venv\Lib\site-packages\django\dispatch\dispatcher.py", line 176, in send
    return [
           ^
  File "C:\Users\Acer\PycharmProjects\PythonProjects\test_progect\venv\Lib\site-packages\django\dispatch\dispatcher.py", line 177, in <listcomp>
    (receiver, receiver(signal=self, sender=sender, **named))
               ^^^^^^^^^^^^^^^^^^^^^^^^^^^^^^^^^^^^^^^^^^^^^
  File "C:\Users\Acer\PycharmProjects\PythonProjects\test_progect\project\news\signals.py", line 20, in New_created
    with_every_new_post.delay(instance.category.title,
  File "C:\Users\Acer\PycharmProjects\PythonProjects\test_progect\venv\Lib\site-packages\celery\app\task.py", line 444, in delay
    return self.apply_async(args, kwargs)
           ^^^^^^^^^^^^^^^^^^^^^^^^^^^^^^
  File "C:\Users\Acer\PycharmProjects\PythonProjects\test_progect\venv\Lib\site-packages\celery\app\task.py", line 594, in apply_async
    return app.send_task(
           ^^^^^^^^^^^^^^
  File "C:\Users\Acer\PycharmProjects\PythonProjects\test_progect\venv\Lib\site-packages\celery\app\base.py", line 795, in send_task
    with P.connection._reraise_as_library_errors():
  File "C:\Users\Acer\AppData\Local\Programs\Python\Python311\Lib\contextlib.py", line 155, in __exit__
    self.gen.throw(typ, value, traceback)
  File "C:\Users\Acer\PycharmProjects\PythonProjects\test_progect\venv\Lib\site-packages\kombu\connection.py", line 476, in _reraise_as_library_errors
    raise ConnectionError(str(exc)) from exc
kombu.exceptions.OperationalError: Error 10061 connecting to localhost:6379. Подключение не установлено, т.к. конечный компьютер отверг запрос на подключение.
2023-11-10 20:52:08,308 - [ERROR] - "POST /admin/news/new/add/ HTTP/1.1" 500 334266 - C:\Users\Acer\PycharmProjects\PythonProjects\test_progect\venv\Lib\site-packages\django\core\servers\basehttp.py - None 
2023-11-10 20:59:54,738 - [ERROR] - Internal Server Error: /admin/news/new/add/ - C:\Users\Acer\PycharmProjects\PythonProjects\test_progect\venv\Lib\site-packages\django\utils\log.py - (<class 'kombu.exceptions.OperationalError'>, OperationalError('Error 10061 connecting to localhost:6379. Подключение не установлено, т.к. конечный компьютер отверг запрос на подключение.'), <traceback object at 0x00000286D1B9AD00>) 
Traceback (most recent call last):
  File "C:\Users\Acer\PycharmProjects\PythonProjects\test_progect\venv\Lib\site-packages\redis\connection.py", line 442, in send_packed_command
    self._sock.sendall(item)
ConnectionResetError: [WinError 10054] Удаленный хост принудительно разорвал существующее подключение

During handling of the above exception, another exception occurred:

Traceback (most recent call last):
  File "C:\Users\Acer\PycharmProjects\PythonProjects\test_progect\venv\Lib\site-packages\celery\backends\redis.py", line 127, in reconnect_on_error
    yield
  File "C:\Users\Acer\PycharmProjects\PythonProjects\test_progect\venv\Lib\site-packages\celery\backends\redis.py", line 177, in _consume_from
    self._pubsub.subscribe(key)
  File "C:\Users\Acer\PycharmProjects\PythonProjects\test_progect\venv\Lib\site-packages\redis\client.py", line 916, in subscribe
    ret_val = self.execute_command("SUBSCRIBE", *new_channels.keys())
              ^^^^^^^^^^^^^^^^^^^^^^^^^^^^^^^^^^^^^^^^^^^^^^^^^^^^^^^
  File "C:\Users\Acer\PycharmProjects\PythonProjects\test_progect\venv\Lib\site-packages\redis\client.py", line 761, in execute_command
    self._execute(connection, connection.send_command, *args, **kwargs)
  File "C:\Users\Acer\PycharmProjects\PythonProjects\test_progect\venv\Lib\site-packages\redis\client.py", line 800, in _execute
    return conn.retry.call_with_retry(
           ^^^^^^^^^^^^^^^^^^^^^^^^^^^
  File "C:\Users\Acer\PycharmProjects\PythonProjects\test_progect\venv\Lib\site-packages\redis\retry.py", line 49, in call_with_retry
    fail(error)
  File "C:\Users\Acer\PycharmProjects\PythonProjects\test_progect\venv\Lib\site-packages\redis\client.py", line 802, in <lambda>
    lambda error: self._disconnect_raise_connect(conn, error),
                  ^^^^^^^^^^^^^^^^^^^^^^^^^^^^^^^^^^^^^^^^^^^
  File "C:\Users\Acer\PycharmProjects\PythonProjects\test_progect\venv\Lib\site-packages\redis\client.py", line 789, in _disconnect_raise_connect
    raise error
  File "C:\Users\Acer\PycharmProjects\PythonProjects\test_progect\venv\Lib\site-packages\redis\retry.py", line 46, in call_with_retry
    return do()
           ^^^^
  File "C:\Users\Acer\PycharmProjects\PythonProjects\test_progect\venv\Lib\site-packages\redis\client.py", line 801, in <lambda>
    lambda: command(*args, **kwargs),
            ^^^^^^^^^^^^^^^^^^^^^^^^
  File "C:\Users\Acer\PycharmProjects\PythonProjects\test_progect\venv\Lib\site-packages\redis\connection.py", line 464, in send_command
    self.send_packed_command(
  File "C:\Users\Acer\PycharmProjects\PythonProjects\test_progect\venv\Lib\site-packages\redis\connection.py", line 453, in send_packed_command
    raise ConnectionError(f"Error {errno} while writing to socket. {errmsg}.")
redis.exceptions.ConnectionError: Error 10054 while writing to socket. Удаленный хост принудительно разорвал существующее подключение.

During handling of the above exception, another exception occurred:

Traceback (most recent call last):
  File "C:\Users\Acer\PycharmProjects\PythonProjects\test_progect\venv\Lib\site-packages\redis\connection.py", line 264, in connect
    sock = self.retry.call_with_retry(
           ^^^^^^^^^^^^^^^^^^^^^^^^^^^
  File "C:\Users\Acer\PycharmProjects\PythonProjects\test_progect\venv\Lib\site-packages\redis\retry.py", line 46, in call_with_retry
    return do()
           ^^^^
  File "C:\Users\Acer\PycharmProjects\PythonProjects\test_progect\venv\Lib\site-packages\redis\connection.py", line 265, in <lambda>
    lambda: self._connect(), lambda error: self.disconnect(error)
            ^^^^^^^^^^^^^^^
  File "C:\Users\Acer\PycharmProjects\PythonProjects\test_progect\venv\Lib\site-packages\redis\connection.py", line 627, in _connect
    raise err
  File "C:\Users\Acer\PycharmProjects\PythonProjects\test_progect\venv\Lib\site-packages\redis\connection.py", line 615, in _connect
    sock.connect(socket_address)
ConnectionRefusedError: [WinError 10061] Подключение не установлено, т.к. конечный компьютер отверг запрос на подключение

During handling of the above exception, another exception occurred:

Traceback (most recent call last):
  File "C:\Users\Acer\PycharmProjects\PythonProjects\test_progect\venv\Lib\site-packages\kombu\connection.py", line 472, in _reraise_as_library_errors
    yield
  File "C:\Users\Acer\PycharmProjects\PythonProjects\test_progect\venv\Lib\site-packages\celery\app\base.py", line 797, in send_task
    self.backend.on_task_call(P, task_id)
  File "C:\Users\Acer\PycharmProjects\PythonProjects\test_progect\venv\Lib\site-packages\celery\backends\redis.py", line 373, in on_task_call
    self.result_consumer.consume_from(task_id)
  File "C:\Users\Acer\PycharmProjects\PythonProjects\test_progect\venv\Lib\site-packages\celery\backends\redis.py", line 170, in consume_from
    self._consume_from(task_id)
  File "C:\Users\Acer\PycharmProjects\PythonProjects\test_progect\venv\Lib\site-packages\celery\backends\redis.py", line 176, in _consume_from
    with self.reconnect_on_error():
  File "C:\Users\Acer\AppData\Local\Programs\Python\Python311\Lib\contextlib.py", line 155, in __exit__
    self.gen.throw(typ, value, traceback)
  File "C:\Users\Acer\PycharmProjects\PythonProjects\test_progect\venv\Lib\site-packages\celery\backends\redis.py", line 130, in reconnect_on_error
    self._ensure(self._reconnect_pubsub, ())
  File "C:\Users\Acer\PycharmProjects\PythonProjects\test_progect\venv\Lib\site-packages\celery\backends\redis.py", line 384, in ensure
    return retry_over_time(
           ^^^^^^^^^^^^^^^^
  File "C:\Users\Acer\PycharmProjects\PythonProjects\test_progect\venv\Lib\site-packages\kombu\utils\functional.py", line 318, in retry_over_time
    return fun(*args, **kwargs)
           ^^^^^^^^^^^^^^^^^^^^
  File "C:\Users\Acer\PycharmProjects\PythonProjects\test_progect\venv\Lib\site-packages\celery\backends\redis.py", line 106, in _reconnect_pubsub
    metas = self.backend.client.mget(self.subscribed_to)
            ^^^^^^^^^^^^^^^^^^^^^^^^^^^^^^^^^^^^^^^^^^^^
  File "C:\Users\Acer\PycharmProjects\PythonProjects\test_progect\venv\Lib\site-packages\redis\commands\core.py", line 2015, in mget
    return self.execute_command("MGET", *args, **options)
           ^^^^^^^^^^^^^^^^^^^^^^^^^^^^^^^^^^^^^^^^^^^^^^
  File "C:\Users\Acer\PycharmProjects\PythonProjects\test_progect\venv\Lib\site-packages\redis\client.py", line 533, in execute_command
    conn = self.connection or pool.get_connection(command_name, **options)
                              ^^^^^^^^^^^^^^^^^^^^^^^^^^^^^^^^^^^^^^^^^^^^
  File "C:\Users\Acer\PycharmProjects\PythonProjects\test_progect\venv\Lib\site-packages\redis\connection.py", line 1086, in get_connection
    connection.connect()
  File "C:\Users\Acer\PycharmProjects\PythonProjects\test_progect\venv\Lib\site-packages\redis\connection.py", line 270, in connect
    raise ConnectionError(self._error_message(e))
redis.exceptions.ConnectionError: Error 10061 connecting to localhost:6379. Подключение не установлено, т.к. конечный компьютер отверг запрос на подключение.

The above exception was the direct cause of the following exception:

Traceback (most recent call last):
  File "C:\Users\Acer\PycharmProjects\PythonProjects\test_progect\venv\Lib\site-packages\django\core\handlers\exception.py", line 55, in inner
    response = get_response(request)
               ^^^^^^^^^^^^^^^^^^^^^
  File "C:\Users\Acer\PycharmProjects\PythonProjects\test_progect\venv\Lib\site-packages\django\core\handlers\base.py", line 197, in _get_response
    response = wrapped_callback(request, *callback_args, **callback_kwargs)
               ^^^^^^^^^^^^^^^^^^^^^^^^^^^^^^^^^^^^^^^^^^^^^^^^^^^^^^^^^^^^
  File "C:\Users\Acer\PycharmProjects\PythonProjects\test_progect\venv\Lib\site-packages\django\contrib\admin\options.py", line 688, in wrapper
    return self.admin_site.admin_view(view)(*args, **kwargs)
           ^^^^^^^^^^^^^^^^^^^^^^^^^^^^^^^^^^^^^^^^^^^^^^^^^
  File "C:\Users\Acer\PycharmProjects\PythonProjects\test_progect\venv\Lib\site-packages\django\utils\decorators.py", line 134, in _wrapper_view
    response = view_func(request, *args, **kwargs)
               ^^^^^^^^^^^^^^^^^^^^^^^^^^^^^^^^^^^
  File "C:\Users\Acer\PycharmProjects\PythonProjects\test_progect\venv\Lib\site-packages\django\views\decorators\cache.py", line 62, in _wrapper_view_func
    response = view_func(request, *args, **kwargs)
               ^^^^^^^^^^^^^^^^^^^^^^^^^^^^^^^^^^^
  File "C:\Users\Acer\PycharmProjects\PythonProjects\test_progect\venv\Lib\site-packages\django\contrib\admin\sites.py", line 242, in inner
    return view(request, *args, **kwargs)
           ^^^^^^^^^^^^^^^^^^^^^^^^^^^^^^
  File "C:\Users\Acer\PycharmProjects\PythonProjects\test_progect\venv\Lib\site-packages\django\contrib\admin\options.py", line 1886, in add_view
    return self.changeform_view(request, None, form_url, extra_context)
           ^^^^^^^^^^^^^^^^^^^^^^^^^^^^^^^^^^^^^^^^^^^^^^^^^^^^^^^^^^^^
  File "C:\Users\Acer\PycharmProjects\PythonProjects\test_progect\venv\Lib\site-packages\django\utils\decorators.py", line 46, in _wrapper
    return bound_method(*args, **kwargs)
           ^^^^^^^^^^^^^^^^^^^^^^^^^^^^^
  File "C:\Users\Acer\PycharmProjects\PythonProjects\test_progect\venv\Lib\site-packages\django\utils\decorators.py", line 134, in _wrapper_view
    response = view_func(request, *args, **kwargs)
               ^^^^^^^^^^^^^^^^^^^^^^^^^^^^^^^^^^^
  File "C:\Users\Acer\PycharmProjects\PythonProjects\test_progect\venv\Lib\site-packages\django\contrib\admin\options.py", line 1747, in changeform_view
    return self._changeform_view(request, object_id, form_url, extra_context)
           ^^^^^^^^^^^^^^^^^^^^^^^^^^^^^^^^^^^^^^^^^^^^^^^^^^^^^^^^^^^^^^^^^^
  File "C:\Users\Acer\PycharmProjects\PythonProjects\test_progect\venv\Lib\site-packages\django\contrib\admin\options.py", line 1798, in _changeform_view
    self.save_model(request, new_object, form, not add)
  File "C:\Users\Acer\PycharmProjects\PythonProjects\test_progect\venv\Lib\site-packages\django\contrib\admin\options.py", line 1227, in save_model
    obj.save()
  File "C:\Users\Acer\PycharmProjects\PythonProjects\test_progect\venv\Lib\site-packages\django\db\models\base.py", line 814, in save
    self.save_base(
  File "C:\Users\Acer\PycharmProjects\PythonProjects\test_progect\venv\Lib\site-packages\django\db\models\base.py", line 892, in save_base
    post_save.send(
  File "C:\Users\Acer\PycharmProjects\PythonProjects\test_progect\venv\Lib\site-packages\django\dispatch\dispatcher.py", line 176, in send
    return [
           ^
  File "C:\Users\Acer\PycharmProjects\PythonProjects\test_progect\venv\Lib\site-packages\django\dispatch\dispatcher.py", line 177, in <listcomp>
    (receiver, receiver(signal=self, sender=sender, **named))
               ^^^^^^^^^^^^^^^^^^^^^^^^^^^^^^^^^^^^^^^^^^^^^
  File "C:\Users\Acer\PycharmProjects\PythonProjects\test_progect\project\news\signals.py", line 20, in New_created
    with_every_new_post.delay(instance.category.title,
  File "C:\Users\Acer\PycharmProjects\PythonProjects\test_progect\venv\Lib\site-packages\celery\app\task.py", line 444, in delay
    return self.apply_async(args, kwargs)
           ^^^^^^^^^^^^^^^^^^^^^^^^^^^^^^
  File "C:\Users\Acer\PycharmProjects\PythonProjects\test_progect\venv\Lib\site-packages\celery\app\task.py", line 594, in apply_async
    return app.send_task(
           ^^^^^^^^^^^^^^
  File "C:\Users\Acer\PycharmProjects\PythonProjects\test_progect\venv\Lib\site-packages\celery\app\base.py", line 795, in send_task
    with P.connection._reraise_as_library_errors():
  File "C:\Users\Acer\AppData\Local\Programs\Python\Python311\Lib\contextlib.py", line 155, in __exit__
    self.gen.throw(typ, value, traceback)
  File "C:\Users\Acer\PycharmProjects\PythonProjects\test_progect\venv\Lib\site-packages\kombu\connection.py", line 476, in _reraise_as_library_errors
    raise ConnectionError(str(exc)) from exc
kombu.exceptions.OperationalError: Error 10061 connecting to localhost:6379. Подключение не установлено, т.к. конечный компьютер отверг запрос на подключение.
2023-11-10 20:59:54,742 - [ERROR] - "POST /admin/news/new/add/ HTTP/1.1" 500 339858 - C:\Users\Acer\PycharmProjects\PythonProjects\test_progect\venv\Lib\site-packages\django\core\servers\basehttp.py - None 
